{
  "registryname": "fluid_mixer",
  "localizedname": "Fluid Mixer",
  "parts": [
    {
      "x": -1,
      "y": 0,
      "z": 0,
      "elements": ["modularmachinery:blockinputputbus@0"]
    },
    {
      "x": -2,
      "y": 0,
      "z": 0,
      "elements": ["modularmachinery:blockcasing@0"]
    },
    {
      "x": 2,
      "y": 2,
      "z": 1,

      "elements": ["minecraft:hopper@0"]
    },
    {
      "x": 1,
      "y": 0,
      "z": 0,
      "elements": ["modularmachinery:blockfluidoutputhatch@0"]
    },
    {
      "x": -3,
      "y": 0,
      "z": 0,
      "elements": ["modularmachinery:blockcasing@0"]
    },
    {
      "x": 3,
      "y": 2,
      "z": 1,

      "elements": ["minecraft:hopper@0"]
    },
    {
      "x": 2,
      "y": 0,
      "z": 0,
      "elements": ["modularmachinery:blockcasing@0"]
    },
    {
      "x": 4,
      "y": 2,
      "z": 1,
      "elements": ["minecraft:glass@0"]
    },
    {
      "x": 3,
      "y": 0,
      "z": 0,
      "elements": ["modularmachinery:blockcasing@0"]
    },
    {
      "x": 4,
      "y": 0,
      "z": 0,
      "elements": ["modularmachinery:blockcasing@0"]
    },
    {
      "x": -3,
      "y": 3,
      "z": 1,
      "elements": ["modularmachinery:blockcasing@0"]
    },
    {
      "x": -3,
      "y": 1,
      "z": 0,
      "elements": ["modularmachinery:blockcasing@0"]
    },
    {
      "x": -2,
      "y": 3,
      "z": 1,
      "elements": ["modularmachinery:blockfluidinputhatch@0"]
    },
    {
      "x": -2,
      "y": 1,
      "z": 0,
      "elements": ["minecraft:glass@0"]
    },
    {
      "x": -1,
      "y": 3,
      "z": 1,
      "elements": ["modularmachinery:blockfluidinputhatch@0"]
    },
    {
      "x": 0,
      "y": 3,
      "z": 1,
      "elements": ["modularmachinery:blockcasing@0"]
    },
    {
      "x": -1,
      "y": 1,
      "z": 0,
      "elements": ["minecraft:glass@0"]
    },
    {
      "x": 1,
      "y": 3,
      "z": 1,
      "elements": ["modularmachinery:blockcasing@0"]
    },
    {
      "x": 0,
      "y": 1,
      "z": 0,
      "elements": ["minecraft:glass@0"]
    },
    {
      "x": 2,
      "y": 3,
      "z": 1,
      "elements": ["modularmachinery:blockfluidinputhatch@0"]
    },
    {
      "x": 1,
      "y": 1,
      "z": 0,
      "elements": ["minecraft:glass@0"]
    },
    {
      "x": 3,
      "y": 3,
      "z": 1,
      "elements": ["modularmachinery:blockfluidinputhatch@0"]
    },
    {
      "x": 2,
      "y": 1,
      "z": 0,
      "elements": ["minecraft:glass@0"]
    },
    {
      "x": 4,
      "y": 3,
      "z": 1,
      "elements": ["modularmachinery:blockcasing@0"]
    },
    {
      "x": 3,
      "y": 1,
      "z": 0,
      "elements": ["minecraft:glass@0"]
    },
    {
      "x": 4,
      "y": 1,
      "z": 0,
      "elements": ["modularmachinery:blockcasing@0"]
    },
    {
      "x": -3,
      "y": 2,
      "z": 0,
      "elements": ["modularmachinery:blockcasing@0"]
    },
    {
      "x": -2,
      "y": 2,
      "z": 0,
      "elements": ["minecraft:glass@0"]
    },
    {
      "x": -1,
      "y": 2,
      "z": 0,
      "elements": ["minecraft:glass@0"]
    },
    {
      "x": 0,
      "y": 2,
      "z": 0,
      "elements": ["minecraft:glass@0"]
    },
    {
      "x": 1,
      "y": 2,
      "z": 0,
      "elements": ["minecraft:glass@0"]
    },
    {
      "x": -3,
      "y": 0,
      "z": 3,
      "elements": ["modularmachinery:blockcasing@0"]
    },
    {
      "x": 2,
      "y": 2,
      "z": 0,
      "elements": ["minecraft:glass@0"]
    },
    {
      "x": 3,
      "y": 2,
      "z": 0,
      "elements": ["minecraft:glass@0"]
    },
    {
      "x": -2,
      "y": 0,
      "z": 3,
      "elements": ["modularmachinery:blockcasing@0"]
    },
    {
      "x": 4,
      "y": 2,
      "z": 0,
      "elements": ["modularmachinery:blockcasing@0"]
    },
    {
      "x": -1,
      "y": 0,
      "z": 3,
      "elements": ["modularmachinery:blockcasing@0"]
    },
    {
      "x": 0,
      "y": 0,
      "z": 3,
      "elements": ["modularmachinery:blockcasing@0"]
    },
    {
      "x": 1,
      "y": 0,
      "z": 3,
      "elements": ["modularmachinery:blockcasing@0"]
    },
    {
      "x": 2,
      "y": 0,
      "z": 3,
      "elements": ["modularmachinery:blockcasing@0"]
    },
    {
      "x": 3,
      "y": 0,
      "z": 3,
      "elements": ["modularmachinery:blockcasing@0"]
    },
    {
      "x": 4,
      "y": 0,
      "z": 3,
      "elements": ["modularmachinery:blockcasing@0"]
    },
    {
      "x": -3,
      "y": 3,
      "z": 0,
      "elements": ["modularmachinery:blockcasing@0"]
    },
    {
      "x": -2,
      "y": 3,
      "z": 0,
      "elements": ["modularmachinery:blockcasing@0"]
    },
    {
      "x": -1,
      "y": 3,
      "z": 0,
      "elements": ["modularmachinery:blockcasing@0"]
    },
    {
      "x": 0,
      "y": 3,
      "z": 0,
      "elements": ["modularmachinery:blockcasing@0"]
    },
    {
      "x": 1,
      "y": 3,
      "z": 0,
      "elements": ["modularmachinery:blockcasing@0"]
    },
    {
      "x": -3,
      "y": 1,
      "z": 3,
      "elements": ["modularmachinery:blockcasing@0"]
    },
    {
      "x": 2,
      "y": 3,
      "z": 0,
      "elements": ["modularmachinery:blockcasing@0"]
    },
    {
      "x": -2,
      "y": 1,
      "z": 3,
      "elements": ["minecraft:glass@0"]
    },
    {
      "x": 3,
      "y": 3,
      "z": 0,
      "elements": ["modularmachinery:blockcasing@0"]
    },
    {
      "x": 4,
      "y": 3,
      "z": 0,
      "elements": ["modularmachinery:blockcasing@0"]
    },
    {
      "x": -1,
      "y": 1,
      "z": 3,
      "elements": ["minecraft:glass@0"]
    },
    {
      "x": 0,
      "y": 1,
      "z": 3,
      "elements": ["minecraft:glass@0"]
    },
    {
      "x": 1,
      "y": 1,
      "z": 3,
      "elements": ["minecraft:glass@0"]
    },
    {
      "x": 2,
      "y": 1,
      "z": 3,
      "elements": ["minecraft:glass@0"]
    },
    {
      "x": 3,
      "y": 1,
      "z": 3,
      "elements": ["minecraft:glass@0"]
    },
    {
      "x": 4,
      "y": 1,
      "z": 3,
      "elements": ["modularmachinery:blockcasing@0"]
    },
    {
      "x": -3,
      "y": 2,
      "z": 3,
      "elements": ["modularmachinery:blockcasing@0"]
    },
    {
      "x": -3,
      "y": 0,
      "z": 2,
      "elements": ["modularmachinery:blockcasing@0"]
    },
    {
      "x": -2,
      "y": 2,
      "z": 3,
      "elements": ["minecraft:glass@0"]
    },
    {
      "x": -2,
      "y": 0,
      "z": 2,
      "elements": ["modularmachinery:blockcasing@0"]
    },
    {
      "x": -1,
      "y": 2,
      "z": 3,
      "elements": ["minecraft:glass@0"]
    },
    {
      "x": 0,
      "y": 2,
      "z": 3,
      "elements": ["minecraft:glass@0"]
    },
    {
      "x": -1,
      "y": 0,
      "z": 2,
      "elements": ["modularmachinery:blockcasing@0"]
    },
    {
      "x": 0,
      "y": 0,
      "z": 2,
      "elements": ["minecraft:cauldron@0"]
    },
    {
      "x": 1,
      "y": 2,
      "z": 3,
      "elements": ["minecraft:glass@0"]
    },
    {
      "x": 2,
      "y": 2,
      "z": 3,
      "elements": ["minecraft:glass@0"]
    },
    {
      "x": 1,
      "y": 0,
      "z": 2,
      "elements": ["minecraft:cauldron@0"]
    },
    {
      "x": 3,
      "y": 2,
      "z": 3,
      "elements": ["minecraft:glass@0"]
    },
    {
      "x": 2,
      "y": 0,
      "z": 2,
      "elements": ["modularmachinery:blockcasing@0"]
    },
    {
      "x": 4,
      "y": 2,
      "z": 3,
      "elements": ["modularmachinery:blockcasing@0"]
    },
    {
      "x": 3,
      "y": 0,
      "z": 2,
      "elements": ["modularmachinery:blockcasing@0"]
    },
    {
      "x": 4,
      "y": 0,
      "z": 2,
      "elements": ["modularmachinery:blockcasing@0"]
    },
    {
      "x": -3,
      "y": 3,
      "z": 3,
      "elements": ["modularmachinery:blockcasing@0"]
    },
    {
      "x": -3,
      "y": 1,
      "z": 2,
      "elements": ["minecraft:glass@0"]
    },
    {
      "x": -2,
      "y": 3,
      "z": 3,
      "elements": ["modularmachinery:blockcasing@0"]
    },
    {
      "x": -2,
      "y": 1,
      "z": 2,
      "elements": ["minecraft:cauldron@0"]
    },
    {
      "x": -1,
      "y": 3,
      "z": 3,
      "elements": ["modularmachinery:blockcasing@0"]
    },
    {
      "x": 0,
      "y": 3,
      "z": 3,
      "elements": ["modularmachinery:blockcasing@0"]
    },
    {
      "x": -1,
      "y": 1,
      "z": 2,
      "elements": ["minecraft:cauldron@0"]
    },
    {
      "x": 1,
      "y": 3,
      "z": 3,
      "elements": ["modularmachinery:blockcasing@0"]
    },
    {
      "x": 0,
      "y": 1,
      "z": 2,
      "elements": ["tconstruct:faucet@3"]
    },
    {
      "x": 2,
      "y": 3,
      "z": 3,
      "elements": ["modularmachinery:blockcasing@0"]
    },
    {
      "x": 1,
      "y": 1,
      "z": 2,
      "elements": ["tconstruct:faucet@2"]
    },
    {
      "x": 3,
      "y": 3,
      "z": 3,
      "elements": ["modularmachinery:blockcasing@0"]
    },
    {
      "x": 2,
      "y": 1,
      "z": 2,
      "elements": ["minecraft:cauldron@0"]
    },
    {
      "x": 4,
      "y": 3,
      "z": 3,
      "elements": ["modularmachinery:blockcasing@0"]
    },
    {
      "x": 3,
      "y": 1,
      "z": 2,
      "elements": ["minecraft:cauldron@0"]
    },
    {
      "x": 4,
      "y": 1,
      "z": 2,
      "elements": ["minecraft:glass@0"]
    },
    {
      "x": -3,
      "y": 2,
      "z": 2,
      "elements": ["minecraft:glass@0"]
    },
    {
      "x": -3,
      "y": 0,
      "z": 1,
      "elements": ["modularmachinery:blockcasing@0"]
    },
    {
      "x": -2,
      "y": 2,
      "z": 2,

      "elements": ["minecraft:hopper@0"]
    },
    {
      "x": -2,
      "y": 0,
      "z": 1,
      "elements": ["modularmachinery:blockcasing@0"]
    },
    {
      "x": -1,
      "y": 2,
      "z": 2,

      "elements": ["minecraft:hopper@0"]
    },
    {
      "x": -1,
      "y": 0,
      "z": 1,
      "elements": ["modularmachinery:blockcasing@0"]
    },
    {
      "x": 0,
      "y": 0,
      "z": 1,
      "elements": ["minecraft:cauldron@0"]
    },
    {
      "x": 2,
      "y": 2,
      "z": 2,

      "elements": ["minecraft:hopper@0"]
    },
    {
      "x": 1,
      "y": 0,
      "z": 1,
      "elements": ["minecraft:cauldron@0"]
    },
    {
      "x": 3,
      "y": 2,
      "z": 2,

      "elements": ["minecraft:hopper@0"]
    },
    {
      "x": 2,
      "y": 0,
      "z": 1,
      "elements": ["modularmachinery:blockcasing@0"]
    },
    {
      "x": 4,
      "y": 2,
      "z": 2,
      "elements": ["minecraft:glass@0"]
    },
    {
      "x": 3,
      "y": 0,
      "z": 1,
      "elements": ["modularmachinery:blockcasing@0"]
    },
    {
      "x": 4,
      "y": 0,
      "z": 1,
      "elements": ["modularmachinery:blockcasing@0"]
    },
    {
      "x": -3,
      "y": 3,
      "z": 2,
      "elements": ["modularmachinery:blockcasing@0"]
    },
    {
      "x": -3,
      "y": 1,
      "z": 1,
      "elements": ["minecraft:glass@0"]
    },
    {
      "x": -2,
      "y": 3,
      "z": 2,
      "elements": ["modularmachinery:blockfluidinputhatch@0"]
    },
    {
      "x": -2,
      "y": 1,
      "z": 1,
      "elements": ["minecraft:cauldron@0"]
    },
    {
      "x": -1,
      "y": 3,
      "z": 2,
      "elements": ["modularmachinery:blockfluidinputhatch@0"]
    },
    {
      "x": 0,
      "y": 3,
      "z": 2,
      "elements": ["modularmachinery:blockcasing@0"]
    },
    {
      "x": -1,
      "y": 1,
      "z": 1,
      "elements": ["minecraft:cauldron@0"]
    },
    {
      "x": 1,
      "y": 3,
      "z": 2,
      "elements": ["modularmachinery:blockcasing@0"]
    },
    {
      "x": 0,
      "y": 1,
      "z": 1,
      "elements": ["tconstruct:faucet@3"]
    },
    {
      "x": 2,
      "y": 3,
      "z": 2,
      "elements": ["modularmachinery:blockfluidinputhatch@0"]
    },
    {
      "x": 1,
      "y": 1,
      "z": 1,
      "elements": ["tconstruct:faucet@2"]
    },
    {
      "x": 3,
      "y": 3,
      "z": 2,
      "elements": ["modularmachinery:blockfluidinputhatch@0"]
    },
    {
      "x": 2,
      "y": 1,
      "z": 1,
      "elements": ["minecraft:cauldron@0"]
    },
    {
      "x": 4,
      "y": 3,
      "z": 2,
      "elements": ["modularmachinery:blockcasing@0"]
    },
    {
      "x": 3,
      "y": 1,
      "z": 1,
      "elements": ["minecraft:cauldron@0"]
    },
    {
      "x": 4,
      "y": 1,
      "z": 1,
      "elements": ["minecraft:glass@0"]
    },
    {
      "x": -3,
      "y": 2,
      "z": 1,
      "elements": ["minecraft:glass@0"]
    },
    {
      "x": -2,
      "y": 2,
      "z": 1,

      "elements": ["minecraft:hopper@0"]
    },
    {
      "x": -1,
      "y": 2,
      "z": 1,

      "elements": ["minecraft:hopper@0"]
    }
  ]
}
